Workbook

Sheet EVA Physics 34 schedule
A1: Week of | B1: Tuesday | C1: Tuesday | D1: Wednesday | E1: Thursday | F1: Thursday Alt
A2: ='Physics 34 2026'!B3 -> 46055 | B2: ='Physics 34 2026'!U3 -> No classes | C2: ='Physics 34 2026'!V3 -> No classes | D2: ='Physics 34 2026'!W3 -> Summer work | E2: ='Physics 34 2026'!X3 -> 1A.1 free-body diagrams & net force | F2: no class
A3: ='Physics 34 2026'!B4 -> 46062 | B3: ='Physics 34 2026'!U4 -> 1A.2 F=ma calculations | C3: ='Physics 34 2026'!V4 -> 1A.3 action-reaction pairs & 1B.1 centripetal force/accel direction | D3: ='Physics 34 2026'!W4 -> 1B.2 Fnet=mv²/r, a=v²/r | E3: ='Physics 34 2026'!X4 -> 1B.3 banked track FBDs & 1B.4 normal force as Fc on banks | F3: ='Physics 34 2026'!Y4 -> 1B.5 Fnet=mg tan θ
A4: ='Physics 34 2026'!B5 -> 46069 | B4: ='Physics 34 2026'!U5 -> 1B.6 vertical circular FBDs & 1B.7 N/T & Fc equations (vertical) | C4: ='Physics 34 2026'!V5 -> 1B.8 v=2πr/T, T=1/f & 1C.1 projectile path & air resistance | D4: ='Physics 34 2026'!W5 -> 1C.2 projectile component calcs | E4: ='Physics 34 2026'!X5 -> 2A.1 W=Fs cos θ & 2A.2 work needs parallel force | F4: no class
A5: ='Physics 34 2026'!B6 -> 46076 | B5: ='Physics 34 2026'!U6 -> Swim | C5: ='Physics 34 2026'!V6 -> Swim | D5: ='Physics 34 2026'!W6 -> 2A.3 work from F-s graph & 2A.4 energy conservation | E5: ='Physics 34 2026'!X6 -> 2A.5 Ek=½mv², Eg=mgΔh | F5: ='Physics 34 2026'!Y6 -> 2A.6 Ek↔Eg transformations
A6: ='Physics 34 2026'!B7 -> 46083 | B6: ='Physics 34 2026'!U7 -> 2B.1 p=mv & 2B.2 momentum conservation | C6: ='Physics 34 2026'!V7 -> 2B.3 elastic vs inelastic | D6: ='Physics 34 2026'!W7 -> 2B.4 I=Δp=mΔv=FΔt & 2B.5 impulse from F-t graph | E6: ='Physics 34 2026'!X7 -> Luna Park | F6: no class
A7: ='Physics 34 2026'!B8 -> 46090 | B7: ='Physics 34 2026'!U8 -> 2C.1 k & Es from F-x graphs & 2C.2 F=–kx, Es=½kx² | C7: ='Physics 34 2026'!V8 -> 2C.3 spring energy transforms & 2C.4 oscillating spring energy & 2C.5 mg=kx equilibrium | D7: ='Physics 34 2026'!W8 -> Catchup / Assessment | E7: ='Physics 34 2026'!X8 -> 3B.1 Eg=mgΔh & 3B.2 GPE from graphs | F7: ='Physics 34 2026'!Y8 -> 3A.1 g-field shape & monopole & 3A.2 inverse square (gravity)
A8: ='Physics 34 2026'!B9 -> 46097 | B8: ='Physics 34 2026'!V9 -> 3C.1 Fg & FN for satellites & 3C.2 a=v²/r=4π²r/T² | C8: ='Physics 34 2026'!W9 -> 4A.1 electric field model & 4A.2 E-field comparisons | D8: ='Physics 34 2026'!X9 -> 4A.3 E-field shape & direction & 4A.4 inverse square (electric) | E8: ='Physics 34 2026'!X9 -> 4A.3 E-field shape & direction & 4A.4 inverse square (electric) | F8: no class
A9: ='Physics 34 2026'!B10 -> 46104 | B9: ='Physics 34 2026'!U10 -> 4A.5 PE changes (qualitative) & 4A.6 static/changing, uniform/non | C9: ='Physics 34 2026'!V10 -> 4A.7 E=kQ/r², E=V/d | D9: ='Physics 34 2026'!W10 -> 4A.8 F=kq₁q₂/r² | E9: ='Physics 34 2026'!X10 -> 4A.9 W=qV | F9: ='Physics 34 2026'!Y10 -> 4A.10 F=qE
A10: ='Physics 34 2026'!B11 -> 46111 | B10: ='Physics 34 2026'!U11 -> Aths | C10: ='Physics 34 2026'!V11 -> Aths | D10: ='Physics 34 2026'!W11 -> 4B.1 magnetic field model & 4B.2 B-field comparisons | E10: ='Physics 34 2026'!X11 -> 4B.3 B-fields: magnets/wires/solenoids & 4B.4 field interactions | F10: no class
A11: holidays | B11: holidays | C11: holidays | D11: holidays | E11: holidays | F11: holidays
A12: ='Physics 34 2026'!B13 -> 46132 | B12: ='Physics 34 2026'!U13 -> 4B.5 F=nIlB | C12: ='Physics 34 2026'!V13 -> 4B.6 DC motor operation & 4B.7 motor torque factors | D12: ='Physics 34 2026'!W13 -> 4B.8 F=qvB, qvB=mv²/r | E12: ='Physics 34 2026'!X13 -> 4B.9 accelerators & UCM | F12: ='Physics 34 2026'!Y13 -> 5A.1 PV cell DC production & 5A.2 PV energy transforms
A13: ='Physics 34 2026'!B14 -> 46139 | B13: ='Physics 34 2026'!U14 -> 5A.3 inverter function & 5A.4 series/parallel PV panels | C13: ='Physics 34 2026'!V14 -> 5B.1 induced emf situations & 5B.2 ΦB=B⊥A, Wb units | D13: ='Physics 34 2026'!W14 -> 5B.3 EM induction explanation | E13: ='Physics 34 2026'!X14 -> 5B.4 ε=−NΔΦ/Δt | F13: no class
A14: ='Physics 34 2026'!B15 -> 46146 | B14: ='Physics 34 2026'!U15 -> 5B.5 Lenz's law | C14: ='Physics 34 2026'!V15 -> 5B.6 induced I needs circuit & 5C.1 DC generator operation | D14: ='Physics 34 2026'!W15 -> 5C.2 split ring commutator role & 5C.3 DC V-t graph shape | E14: ='Physics 34 2026'!X15 -> 5C.4 V-t graphs vs coil number & 5D.1 AC generator operation | F14: ='Physics 34 2026'!Y15 -> 5D.2 slip rings role & 5D.3 sinusoidal V-t analysis
A15: ='Physics 34 2026'!B16 -> 46153 | B15: ='Physics 34 2026'!U16 -> 6A.1 Vrms=Vp/√2 | C15: ='Physics 34 2026'!V16 -> 6A.2 Irms=Ip/√2 & 6A.3 P=VrmsIrms | D15: ='Physics 34 2026'!W16 -> 6B.1 transformers & flux & 6B.2 step-up/step-down | E15: ='Physics 34 2026'!X16 -> 6B.3 ideal vs real transformers & 6B.4 N₁/N₂=V₁/V₂=I₂/I₁ | F15: no class
A16: ='Physics 34 2026'!B17 -> 46160 | B16: ='Physics 34 2026'!U17 -> 6B.5 turns ratio calcs | C16: ='Physics 34 2026'!V17 -> 6C.1 P=I²R, E=I²Rt | D16: ='Physics 34 2026'!W17 -> 6C.2 transmission losses | E16: ='Physics 34 2026'!X17 -> Catchup / Assessment | F16: ='Physics 34 2026'!Y17 -> Catchup / Assessment
A17: ='Physics 34 2026'!B18 -> 46167 | B17: ='Physics 34 2026'!U18 -> 7A.1 accel charges → EM waves & 7A.2 EM waves: E⊥B at c | C17: ='Physics 34 2026'!V18 -> 7A.3 superposition → standing waves | D17: ='Physics 34 2026'!W18 -> 7A.4 standing wave analysis | E17: ='Physics 34 2026'!X18 -> 7A.5 diffraction & gap width & 7A.6 λ/w ratio & imaging | F17: no class
A18: ='Physics 34 2026'!B19 -> 46174 | B18: ='Physics 34 2026'!U19 -> 7A.7 Young's double slit | C18: ='Physics 34 2026'!V19 -> 7A.8 path diff: nλ, (n+½)λ | D18: ='Physics 34 2026'!W19 -> 7A.9 Δx=λL/d | E18: ='Physics 34 2026'!X19 -> 7B.1 E=hf=hc/λ | F18: ='Physics 34 2026'!Y19 -> 7B.2 photoelectric evidence
A19: ='Physics 34 2026'!B20 -> 46181 | B19: ='Physics 34 2026'!U20 -> King's Birthday | C19: ='Physics 34 2026'!V20 -> King's Birthday | D19: ='Physics 34 2026'!W20 -> 7B.3 photoelectric graphs | E19: ='Physics 34 2026'!X20 -> 8A.1 electron diffraction patterns | F19: no class
A20: ='Physics 34 2026'!B21 -> 46188 | B20: ='Physics 34 2026'!U21 -> 8A.2 diffraction → wave nature | C20: ='Physics 34 2026'!V21 -> 8A.3 photon vs electron patterns | D20: ='Physics 34 2026'!W21 -> GAT | E20: ='Physics 34 2026'!X21 -> 8A.4 λ=h/p | F20: ='Physics 34 2026'!Y21 -> 8B.1 quantisation concepts & 8B.2 p=h/λ
A21: ='Physics 34 2026'!B22 -> 46195 | B21: ='Physics 34 2026'!U22 -> 8B.3 photon vs matter momentum & 8B.4 emission spectra | C21: ='Physics 34 2026'!V22 -> HPA | D21: ='Physics 34 2026'!W22 -> HPA | E21: ='Physics 34 2026'!X22 -> HPA | F21: no class
A22: holidays | B22: holidays | C22: holidays | D22: holidays | E22: holidays | F22: holidays
A23: ='Physics 34 2026'!B24 -> 46223 | B23: ='Physics 34 2026'!U24 -> 8B.5 absorption spectra | C23: ='Physics 34 2026'!V24 -> 8B.6 ΔE=hc/λ from spectra | D23: ='Physics 34 2026'!W24 -> 8B.7 ΔE=hf transitions | E23: ='Physics 34 2026'!X24 -> 8B.8 single particle duality | F23: ='Physics 34 2026'!Y24 -> 9A.1 inertial frames & 9A.2 inertial vs non-inertial
A24: ='Physics 34 2026'!B25 -> 46230 | B24: ='Physics 34 2026'!U25 -> 9A.3 relativity concept | C24: ='Physics 34 2026'!V25 -> 9A.4 SR postulates | D24: ='Physics 34 2026'!W25 -> 9A.5 Michelson-Morley & aether & 9A.6 SR vs classical | E24: ='Physics 34 2026'!X25 -> 9B.1 proper time t₀ & 9B.2 dilated time t | F24: no class
A25: ='Physics 34 2026'!B26 -> 46237 | B25: ='Physics 34 2026'!U26 -> 9B.3 proper length L₀ & 9B.4 identify proper length | C25: ='Physics 34 2026'!V26 -> 9B.5 contraction direction | D25: ='Physics 34 2026'!W26 -> 9B.6 L=L₀/γ, t=t₀γ | E25: ='Physics 34 2026'!X26 -> 9B.7 accelerators & l.c. & 9B.8 GPS & time dilation | F25: ='Physics 34 2026'!Y26 -> 9B.9 speed effects on t,L & 9C.1 muon t dilation (Earth)
A26: ='Physics 34 2026'!B27 -> 46244 | B26: ='Physics 34 2026'!U27 -> 9C.2 muon l.c. (muon frame) & 9D.1 E=mc² | C26: ='Physics 34 2026'!V27 -> 9D.2 Etot=γmc², Ek=(γ–1)mc² | D26: ='Physics 34 2026'!W27 -> 9D.3 ΔE=Δmc² & 9D.4 accelerators → new elements & 9D.5 γ vs v graph | E26: ='Physics 34 2026'!X27 -> Catchup / Assessment | F26: no class
A27: ='Physics 34 2026'!B28 -> 46251 | B27: ='Physics 34 2026'!U28 -> Catchup / Assessment | C27: ='Physics 34 2026'!V28 -> Catchup / Assessment | D27: ='Physics 34 2026'!W28 -> Investigation planning | E27: ='Physics 34 2026'!X28 -> Investigation planning | F27: ='Physics 34 2026'!Y28 -> Investigation planning
A28: ='Physics 34 2026'!B29 -> 46258 | B28: ='Physics 34 2026'!U29 -> 9 Periods SAC Investigation SACU4AOS2 | C28: ='Physics 34 2026'!V29 -> Investigation | D28: ='Physics 34 2026'!W29 -> Investigation | E28: ='Physics 34 2026'!X29 -> Investigation | F28: =IF('Physics 34 2026'!Y29="No class","",'Physics 34 2026'!Y29)
A29: ='Physics 34 2026'!B30 -> 46265 | B29: ='Physics 34 2026'!U30 -> Investigation | C29: ='Physics 34 2026'!V30 -> Investigation | D29: ='Physics 34 2026'!W30 -> Investigation | E29: ='Physics 34 2026'!X30 -> Investigation | F29: ='Physics 34 2026'!Y30 -> Investigation
A30: ='Physics 34 2026'!B31 -> 46272 | B30: ='Physics 34 2026'!U31 -> Practice Exams | C30: ='Physics 34 2026'!V31 -> Practice Exams | D30: ='Physics 34 2026'!W31 -> Practice Exams | E30: ='Physics 34 2026'!X31 -> Practice Exams | F30: =IF('Physics 34 2026'!Y31="No class","",'Physics 34 2026'!Y31)
A31: ='Physics 34 2026'!B32 -> 46279 | B31: ='Physics 34 2026'!U32 -> Practice Exams | C31: ='Physics 34 2026'!V32 -> Practice Exams | D31: ='Physics 34 2026'!W32 -> Practice Exams | E31: ='Physics 34 2026'!X32 -> Practice Exams | F31: ='Physics 34 2026'!Y32 -> Practice Exams
A32: Swot vac | B32: Swot vac | C32: Swot vac | D32: Swot vac | E32: Swot vac | F32: Swot vac
A33: ='Physics 34 2026'!B34 -> 46300 | B33: ='Physics 34 2026'!U34 -> Practice Exams | C33: ='Physics 34 2026'!V34 -> Practice Exams | D33: ='Physics 34 2026'!W34 -> Practice Exams | E33: ='Physics 34 2026'!X34 -> Practice Exams | F33: =IF('Physics 34 2026'!Y34="No class","",'Physics 34 2026'!Y34)
A34: ='Physics 34 2026'!B35 -> 46307 | B34: ='Physics 34 2026'!U35 -> Practice Exams | C34: ='Physics 34 2026'!V35 -> Practice Exams | D34: ='Physics 34 2026'!W35 -> Practice Exams | E34: ='Physics 34 2026'!X35 -> Practice Exams | F34: ='Physics 34 2026'!Y35 -> Practice Exams
A35: ='Physics 34 2026'!B36 -> 46314 | B35: ='Physics 34 2026'!U36 -> 12 Val
A36: ='Physics 34 2026'!B37 -> 46321
A37: ='Physics 34 2026'!B38 -> 46328 | B37: ='Physics 34 2026'!U38 -> Cup Weekend | C37: ='Physics 34 2026'!V38 -> Cup Weekend | D37: ='Physics 34 2026'!W38 -> Cup Weekend
A38: ='Physics 34 2026'!B39 -> 46335

Sheet JIM Physics 34 schedule
A1: Week of | B1: Monday | C1: Monday Alt | D1: Wednesday | E1: Thursday | F1: Thursday
A2: ='Physics 34 2026'!B3 -> 46055 | B2: ='Physics 34 2026'!J3 -> No classes | C2: ='Physics 34 2026'!K3 -> No classes | D2: ='Physics 34 2026'!L3 -> 1A.1 free-body diagrams & net force | E2: ='Physics 34 2026'!M3 -> 1A.2 F=ma calculations | F2: ='Physics 34 2026'!N3 -> 1A.3 action-reaction pairs & 1B.1 centripetal force/accel direction
A3: ='Physics 34 2026'!B4 -> 46062 | B3: ='Physics 34 2026'!J4 -> 1B.2 Fnet=mv²/r, a=v²/r | C3: ='Physics 34 2026'!K4 -> No class | D3: ='Physics 34 2026'!L4 -> 1B.3 banked track FBDs & 1B.4 normal force as Fc on banks | E3: ='Physics 34 2026'!M4 -> 1B.5 Fnet=mg tan θ | F3: ='Physics 34 2026'!N4 -> 1B.6 vertical circular FBDs & 1B.7 N/T & Fc equations (vertical)
A4: ='Physics 34 2026'!B5 -> 46069 | B4: ='Physics 34 2026'!J5 -> 1B.8 v=2πr/T, T=1/f & 1C.1 projectile path & air resistance | C4: ='Physics 34 2026'!K5 -> 1C.2 projectile component calcs | D4: ='Physics 34 2026'!L5 -> 2A.1 W=Fs cos θ & 2A.2 work needs parallel force | E4: ='Physics 34 2026'!M5 -> 2A.3 work from F-s graph & 2A.4 energy conservation | F4: ='Physics 34 2026'!N5 -> 2A.5 Ek=½mv², Eg=mgΔh
A5: ='Physics 34 2026'!B6 -> 46076 | B5: ='Physics 34 2026'!J6 -> 2A.6 Ek↔Eg transformations | C5: ='Physics 34 2026'!K6 -> No class | D5: ='Physics 34 2026'!L6 -> 2B.1 p=mv & 2B.2 momentum conservation | E5: ='Physics 34 2026'!M6 -> 2B.3 elastic vs inelastic | F5: ='Physics 34 2026'!N6 -> 2B.4 I=Δp=mΔv=FΔt & 2B.5 impulse from F-t graph
A6: ='Physics 34 2026'!B7 -> 46083 | B6: ='Physics 34 2026'!J7 -> 2C.1 k & Es from F-x graphs & 2C.2 F=–kx, Es=½kx² | C6: ='Physics 34 2026'!K7 -> 2C.3 spring energy transforms & 2C.4 oscillating spring energy & 2C.5 mg=kx equilibrium | D6: ='Physics 34 2026'!L7 -> Catchup / Assessment | E6: ='Physics 34 2026'!M7 -> Luna Park | F6: ='Physics 34 2026'!N7 -> Luna Park
A7: ='Physics 34 2026'!B8 -> 46090 | B7: ='Physics 34 2026'!J8 -> Labour Day | C7: ='Physics 34 2026'!K8 -> Labour Day | D7: ='Physics 34 2026'!L8 -> 3A.1 g-field shape & monopole & 3A.2 inverse square (gravity) | E7: ='Physics 34 2026'!M8 -> 3A.3 g=GM/r², Fg=Gm₁m₂/r² | F7: ='Physics 34 2026'!N8 -> 4A.1 electric field model & 4A.2 E-field comparisons
A8: ='Physics 34 2026'!B9 -> 46097 | B8: ='Physics 34 2026'!J9 -> 3B.1 Eg=mgΔh & 3B.2 GPE from graphs | C8: ='Physics 34 2026'!K9 -> 3C.1 Fg & FN for satellites & 3C.2 a=v²/r=4π²r/T² | D8: ='Physics 34 2026'!L9 -> 4A.3 E-field shape & direction & 4A.4 inverse square (electric) | E8: ='Physics 34 2026'!M9 -> 4A.5 PE changes (qualitative) & 4A.6 static/changing, uniform/non | F8: ='Physics 34 2026'!N9 -> 4A.7 E=kQ/r², E=V/d
A9: ='Physics 34 2026'!B10 -> 46104 | B9: ='Physics 34 2026'!J10 -> 4A.8 F=kq₁q₂/r² | C9: ='Physics 34 2026'!K10 -> No class | D9: ='Physics 34 2026'!L10 -> 4A.9 W=qV | E9: ='Physics 34 2026'!M10 -> 4A.10 F=qE | F9: ='Physics 34 2026'!N10 -> 4B.1 magnetic field model & 4B.2 B-field comparisons
A10: ='Physics 34 2026'!B11 -> 46111 | B10: ='Physics 34 2026'!J11 -> 4B.3 B-fields: magnets/wires/solenoids & 4B.4 field interactions | C10: ='Physics 34 2026'!K11 -> 4B.5 F=nIlB | D10: ='Physics 34 2026'!L11 -> 4B.6 DC motor operation & 4B.7 motor torque factors | E10: ='Physics 34 2026'!M11 -> 4B.8 F=qvB, qvB=mv²/r | F10: ='Physics 34 2026'!N11 -> 4B.9 accelerators & UCM
A12: ='Physics 34 2026'!B13 -> 46132 | B12: ='Physics 34 2026'!J13 -> Secondary Assembly | C12: ='Physics 34 2026'!K13 -> No class | D12: ='Physics 34 2026'!L13 -> 5A.1 PV cell DC production & 5A.2 PV energy transforms | E12: ='Physics 34 2026'!M13 -> 5A.3 inverter function & 5A.4 series/parallel PV panels | F12: ='Physics 34 2026'!N13 -> 5B.1 induced emf situations & 5B.2 ΦB=B⊥A, Wb units
A13: ='Physics 34 2026'!B14 -> 46139 | B13: ='Physics 34 2026'!J14 -> 5B.3 EM induction explanation | C13: ='Physics 34 2026'!K14 -> 5B.4 ε=−NΔΦ/Δt | D13: ='Physics 34 2026'!L14 -> 5B.5 Lenz's law | E13: ='Physics 34 2026'!M14 -> 5B.6 induced I needs circuit & 5C.1 DC generator operation | F13: ='Physics 34 2026'!N14 -> 5C.2 split ring commutator role & 5C.3 DC V-t graph shape
A14: ='Physics 34 2026'!B15 -> 46146 | B14: ='Physics 34 2026'!J15 -> 5C.4 V-t graphs vs coil number & 5D.1 AC generator operation | C14: ='Physics 34 2026'!K15 -> No class | D14: ='Physics 34 2026'!L15 -> 5D.2 slip rings role & 5D.3 sinusoidal V-t analysis | E14: ='Physics 34 2026'!M15 -> 6A.1 Vrms=Vp/√2 | F14: ='Physics 34 2026'!N15 -> 6A.2 Irms=Ip/√2 & 6A.3 P=VrmsIrms
... A34: ='Physics 34 2026'!B35 -> 46307 | B34: ='Physics 34 2026'!J35 -> Practice Exams | C34: ='Physics 34 2026'!K35 -> No class | D34: ='Physics 34 2026'!L35 -> Practice Exams | E34: ='Physics 34 2026'!M35 -> Practice Exams | F34: ='Physics 34 2026'!N35 -> Practice Exams
A35: ='Physics 34 2026'!B36 -> 46314 | B35: ='Physics 34 2026'!J36 -> 12 Val
A36: ='Physics 34 2026'!B37 -> 46321 | C36: ='Physics 34 2026'!K37 -> No class
A37: ='Physics 34 2026'!B38 -> 46328 | B37: ='Physics 34 2026'!J38 -> Cup Weekend | C37: ='Physics 34 2026'!K38 -> Cup Weekend
A38: ='Physics 34 2026'!B39 -> 46335

Sheet JIM Physics12 schedule
A1: Week of | B1: Monday | C1: Wednesday | D1: Thursday | E1: Thursday | F1: Friday
A2: ='Physics 12 2026'!B2 -> 46055 | B2: ='Physics 12 2026'!K2 -> No classes | C2: ='Physics 12 2026'!L2 -> No classes | D2: ='Physics 12 2026'!M2 -> 1A.1 wave motion examples; 1A.2 energy transfer no matter | E2: ='Physics 12 2026'!N2 -> 1A.3 transverse vs longitudinal | F2: ='Physics 12 2026'!O2 -> 1A.4 A, v, f, T, λ wave terms; 1A.5 λ from v (medium) & f (source)
A3: ='Physics 12 2026'!B3 -> 46062 | B3: ='Physics 12 2026'!K3 -> 1A.6 λ = v/f = vT calculations | C3: ='Physics 12 2026'!L3 -> 1B.1 EM waves transverse E&M fields; 1B.2 Sun emits UV, visible, IR | D3: ='Physics 12 2026'!M3 -> 1B.3 EM spectrum λ & f ranges; 1B.4 EM spectrum societal uses | E3: ='Physics 12 2026'!N3 -> No class | F3: ='Physics 12 2026'!O3 -> 1C.1 ray model reflection/refraction; 1C.2 refractive index definition
A4: ='Physics 12 2026'!B4 -> 46069 | B4: ='Physics 12 2026'!K4 -> 1C.3 n₁v₁ = n₂v₂ equation | C4: ='Physics 12 2026'!L4 -> 1C.4 Snell's law practicals; 1C.5 Snell's law refraction calcs | D4: ='Physics 12 2026'!M4 -> 1C.6 ray model image formation | E4: ='Physics 12 2026'!N4 -> 1C.7 total internal reflection pracs; 1C.8 critical angle prediction | F4: ='Physics 12 2026'!O4 -> 1C.9 dispersion practicals
A5: ='Physics 12 2026'!B5 -> 46076 | B5: ='Physics 12 2026'!K5 -> 1C.10 dispersion in prisms/lenses; 1C.11 rainbows & mirages formation | C5: ='Physics 12 2026'!L5 -> 1C.12 Snell's law optical fibres | D5: ='Physics 12 2026'!M5 -> 2A.1 thermal energy = Ek + Ep; 2A.2 temp ↔ thermal energy | E5: ='Physics 12 2026'!N5 -> No class | F5: ='Physics 12 2026'!O5 -> 2A.3 Celsius ↔ kelvin conversion; 2A.4 conduction/convection/radiation
A6: ='Physics 12 2026'!B6 -> 46083 | B6: ='Physics 12 2026'!K6 -> 2A.5 specific heat capacity c | C6: ='Physics 12 2026'!L6 -> 2A.6 latent heat L definition; 2A.7 temp/state change practicals | D6: ='Physics 12 2026'!M6 -> 2A.8 thermal energy change analysis; 2A.9 Q = mcΔT calculations | E6: ='Physics 12 2026'!N6 -> 2A.10 Q = mL calculations | F6: ='Physics 12 2026'!O6 -> 2B.1 blackbody features
A7: ='Physics 12 2026'!B7 -> 46090 | B7: ='Physics 12 2026'!K7 -> Labour Day | C7: ='Physics 12 2026'!L7 -> Labour Day | D7: ='Physics 12 2026'!M7 -> 2B.2 Wien's law λₘₐₓT = 2.90×10⁻³; 2B.3 blackbody total energy graphs | E7: ='Physics 12 2026'!N7 -> No class | F7: ='Physics 12 2026'!O7 -> 2B.4 thermal/EM radiation concepts
A8: ='Physics 12 2026'!B8 -> 46097 | B8: ='Physics 12 2026'!K8 -> 3A.1 proton:neutron ratio stability; 3A.2 electrostatic/strong/weak forces | C8: ='Physics 12 2026'!L8 -> 3A.3 electrostatic repulsion in nucleus | D8: ='Physics 12 2026'!M8 -> 3A.4 strong nuclear force overcomes; 3A.5 weak force p↔n transformation | E8: ='Physics 12 2026'!N8 -> 3A.6 binding energy curve | F8: ='Physics 12 2026'!O8 -> AT U1AOS1
A9: ='Physics 12 2026'!B9 -> 46104 | B9: ='Physics 12 2026'!K9 -> 3B.1 α, β⁻, β⁺, γ properties; 3B.2 decay equations α, β⁻, β⁺, γ | C9: ='Physics 12 2026'!L9 -> 3C.1 half-life concept; 3C.2 activity after n half-lives | D9: ='Physics 12 2026'!M9 -> 3D.1 decay chains (e.g. U-238) | E9: ='Physics 12 2026'!N9 -> No class | F9: ='Physics 12 2026'!O9 -> VCE Formal
A10: ='Physics 12 2026'!B10 -> 46111 | B10: ='Physics 12 2026'!K10 -> 3E.1 radiation effects on humans; 3E.2 α, β, γ cell damage capacity | C10: ='Physics 12 2026'!L10 -> 3E.3 low/high dose short/long term | D10: ='Physics 12 2026'!M10 -> 3E.4 external vs internal sources; 3E.5 gray, sievert dose calcs | E10: ='Physics 12 2026'!N10 -> 3E.6 medical radioisotopes therapy | F10: ='Physics 12 2026'!O10 -> Good Friday
A12: ='Physics 12 2026'!B12 -> 46132 | B12: ='Physics 12 2026'!K12 -> 4A.1 E = mc² nuclear energy; 4A.2 fission chain reactions | C12: ='Physics 12 2026'!L12 -> 4A.3 mass/shape criticality; 4A.4 neutron absorbers & moderators | D12: ='Physics 12 2026'!M12 -> 4B.1 fusion vs fission comparison; 4B.2 binding energy curve fusion/fission | E12: ='Physics 12 2026'!N12 -> No class | F12: ='Physics 12 2026'!O12 -> 4C.1 nuclear viability Australia; 4C.2 nuclear pros/cons Australia
A13: ='Physics 12 2026'!B13 -> 46139 | B13: ='Physics 12 2026'!K13 -> 5A.1 metal = sea of electrons; 5A.2 current = drift velocity e⁻ | C13: ='Physics 12 2026'!L13 -> 5A.3 charge/current analogies | D13: ='Physics 12 2026'!M13 -> 5A.4 circuit symbols & diagrams; 5A.5 ammeter measures current | E13: ='Physics 12 2026'!N13 -> 5A.6 I = Q/t calculations | F13: ='Physics 12 2026'!O13 -> AT U1AOS2
A14: ='Physics 12 2026'!B14 -> 46146 | B14: ='Physics 12 2026'!K14 -> 5B.1 charge separation = V = energy; 5B.2 V = E/Q and E = VIt | C14: ='Physics 12 2026'!L14 -> 5B.3 voltage/current analogies; 5B.4 voltmeter measures V | D14: ='Physics 12 2026'!M14 -> 5B.5 ammeter series, voltmeter parallel | E14: ='Physics 12 2026'!N14 -> No class | F14: ='Physics 12 2026'!O14 -> 5C.1 I-V for ohmic resistance; 5C.2 R = V/I Ohm's law
... A39: ='Physics 12 2026'!B39 -> 46342 | B39: ='Physics 12 2026'!K39 -> 10-11 exams | C39: ='Physics 12 2026'!L39 -> 10-11 exams | D39: ='Physics 12 2026'!M39 -> 10-11 exams | E39: ='Physics 12 2026'!N39 -> 10-11 exams | F39: ='Physics 12 2026'!O39 -> 10-11 exams
A40: ='Physics 12 2026'!B40 -> 46349 | B40: ='Physics 12 2026'!K40 -> VCE Camp | C40: ='Physics 12 2026'!L40 -> VCE Camp | D40: ='Physics 12 2026'!M40 -> VCE Camp | E40: ='Physics 12 2026'!N40 -> Students Cease

Sheet Physics 34 2026
D1: JIM | E1: JIM | O1: EVA | P1: EVA
A2: When | B2: Week of | D2: Periods | E2: M | F2: T | G2: W | H2: T | I2: F | J2: Monday | K2: Monday | L2: Wednesday | M2: Thursday | N2: Thursday | O2: Periods | P2: M | Q2: T | R2: W | S2: T | T2: F | U2: Tuesday | V2: Tuesday | W2: Wednesday | X2: Thursday | Y2: Thursday
A3: 44927 | B3: 46055 | C3: A | D3: =SUM(E3:I3) -> 3 | E3: No classes | F3: Founders Day Assembly | G3: 1 | H3: 2 | J3: No classes | K3: No classes | L3: 1A.1 free-body diagrams & net force | M3: 1A.2 F=ma calculations | N3: 1A.3 action-reaction pairs & 1B.1 centripetal force/accel direction | O3: =SUM(P3:T3) -> 2 | P3: No classes | Q3: Founders Day Assembly | R3: 1 | S3: 1 | U3: No classes | V3: No classes | W3: Summer work | X3: 1A.1 free-body diagrams & net force | Y3: No class | Z3: 1A [2.5p] Newton's laws | AA3: 1 | AB3: 1A.1 free-body diagrams & net force | AC3: 1A.1: Apply Newton's first law to draw free-body diagrams and determine if net force acting [1p]
A4: 44928 | B4: =B3+7 -> 46062 | C4: B | D4: =SUM(E4:I4) -> 4 | E4: 1 | F4: Swim | G4: 1 | H4: 2 | J4: 1B.2 Fnet=mv²/r, a=v²/r | K4: No class | L4: 1B.3 banked track FBDs & 1B.4 normal force as Fc on banks | M4: 1B.5 Fnet=mg tan θ | N4: 1B.6 vertical circular FBDs & 1B.7 N/T & Fc equations (vertical) | O4: =SUM(P4:T4) -> 3 | Q4: Swim | R4: 1 | S4: 2 | U4: 1A.2 F=ma calculations | V4: 1A.3 action-reaction pairs & 1B.1 centripetal force/accel direction | W4: 1B.2 Fnet=mv²/r, a=v²/r | X4: 1B.3 banked track FBDs & 1B.4 normal force as Fc on banks | Y4: 1B.5 Fnet=mg tan θ | Z4: 1A [2.5p] Newton's laws | AA4: 2 | AB4: 1A.2 F=ma calculations | AC4: 1A.2: Apply Newton's second law (Fnet = ma) to calculate acceleration or forces [1p]
A5: 44929 | B5: =B4+7 -> 46069 | C5: A | D5: =SUM(E5:I5) -> 5 | E5: 2 | G5: 1 | H5: 2 | J5: 1B.8 v=2πr/T, T=1/f & 1C.1 projectile path & air resistance | K5: 1C.2 projectile component calcs | L5: 2A.1 W=Fs cos θ & 2A.2 work needs parallel force | M5: 2A.3 work from F-s graph & 2A.4 energy conservation | N5: 2A.5 Ek=½mv², Eg=mgΔh | O5: =SUM(P5:T5) -> 4 | Q5: 2 | R5: 1 | S5: 1 | U5: 1B.6 vertical circular FBDs & 1B.7 N/T & Fc equations (vertical) | V5: 1B.8 v=2πr/T, T=1/f & 1C.1 projectile path & air resistance | W5: 1C.2 projectile component calcs | X5: 2A.1 W=Fs cos θ & 2A.2 work needs parallel force | Y5: No class | Z5: 1A [2.5p] Newton's laws | AA5: 3 | AB5: 1A.3 action-reaction pairs | AC5: 1A.3: Apply Newton's third law to identify action–reaction force pairs [0.5p]
A6: 44930 | B6: =B5+7 -> 46076 | C6: B | D6: =SUM(E6:I6) -> 4 | E6: 1 | G6: 1 | H6: 2 | J6: 2A.6 Ek↔Eg transformations | K6: No class | L6: 2B.1 p=mv & 2B.2 momentum conservation | M6: 2B.3 elastic vs inelastic | N6: 2B.4 I=Δp=mΔv=FΔt & 2B.5 impulse from F-t graph | O6: =SUM(P6:T6) -> 5 | Q6: 2 | R6: 1 | S6: 2 | U6: Swim | V6: Swim | W6: 2A.3 work from F-s graph & 2A.4 energy conservation | X6: 2A.5 Ek=½mv², Eg=mgΔh | Y6: 2A.6 Ek↔Eg transformations | Z6: 1B [5.25p] Circular motion | AA6: 4 | AB6: 1B.1 centripetal force/accel direction | AC6: 1B.1: Understand centripetal force and acceleration direction in uniform circular motion [0.5p]
A7: 44931 | B7: =B6+7 -> 46083 | C7: A | D7: =SUM(E7:I7) -> 5 | E7: 2 | G7: 1 | H7: 2 | J7: 2C.1 k & Es from F-x graphs & 2C.2 F=–kx, Es=½kx² | K7: 2C.3 spring energy transforms & 2C.4 oscillating spring energy & 2C.5 mg=kx equilibrium | L7: Catchup / Assessment | M7: Luna Park | N7: Luna Park | O7: =SUM(P7:T7) -> 4 | Q7: 2 | R7: 1 | S7: 1 | U7: 2B.1 p=mv & 2B.2 momentum conservation | V7: 2B.3 elastic vs inelastic | W7: 2B.4 I=Δp=mΔv=FΔt & 2B.5 impulse from F-t graph | X7: Luna Park | Y7: No class | Z7: 1B [5.25p] Circular motion | AA7: 5 | AB7: 1B.2 Fnet=mv²/r, a=v²/r | AC7: 1B.2: Apply formulas Fnet = mv²/r and a = v²/r for horizontal circular motion [1p]
A8: 44932 | B8: =B7+7 -> 46090 | C8: B | D8: =SUM(E8:I8) -> 3 | E8: Labour Day | G8: 1 | H8: 2 | J8: Labour Day | K8: Labour Day | L8: 3A.1 g-field shape & monopole & 3A.2 inverse square (gravity) | M8: 3A.3 g=GM/r², Fg=Gm₁m₂/r² | N8: 4A.1 electric field model & 4A.2 E-field comparisons | O8: =SUM(P8:T8) -> 5 | P8: Labour Day | Q8: 2 | R8: 1 | S8: 2 | U8: 2C.1 k & Es from F-x graphs & 2C.2 F=–kx, Es=½kx² | V8: 2C.3 spring energy transforms & 2C.4 oscillating spring energy & 2C.5 mg=kx equilibrium | W8: Catchup / Assessment | X8: 3B.1 Eg=mgΔh & 3B.2 GPE from graphs | Y8: 3A.1 g-field shape & monopole & 3A.2 inverse square (gravity) | Z8: 1B [5.25p] Circular motion | AA8: 6 | AB8: 1B.3 banked track FBDs | AC8: 1B.3: Draw free-body diagrams for vehicles on banked tracks [0.5p]
A9: 44933 | B9: =B8+7 -> 46097 | C9: A | D9: =SUM(E9:I9) -> 5 | E9: 2 | G9: 1 | H9: 2 | J9: 3B.1 Eg=mgΔh & 3B.2 GPE from graphs | K9: 3C.1 Fg & FN for satellites & 3C.2 a=v²/r=4π²r/T² | L9: 4A.3 E-field shape & direction & 4A.4 inverse square (electric) | M9: 4A.5 PE changes (qualitative) & 4A.6 static/changing, uniform/non | N9: 4A.7 E=kQ/r², E=V/d | O9: =SUM(P9:T9) -> 4 | Q9: 2 | R9: 1 | S9: 1 | U9: 3A.3 g=GM/r², Fg=Gm₁m₂/r² | V9: 3C.1 Fg & FN for satellites & 3C.2 a=v²/r=4π²r/T² | W9: 4A.1 electric field model & 4A.2 E-field comparisons | X9: 4A.3 E-field shape & direction & 4A.4 inverse square (electric) | Y9: No class | Z9: 1B [5.25p] Circular motion | AA9: 7 | AB9: 1B.4 normal force as Fc on banks | AC9: 1B.4: Explain horizontal component of normal force as centripetal force on frictionless banked tracks [0.5p]
A10: 44934 | B10: =B9+7 -> 46104 | C10: B | D10: =SUM(E10:I10) -> 4 | E10: 1 | F10: SACU3AOS1 Monday B Afternoon | G10: 1 | H10: 2 | I10: VCE Formal | J10: 4A.8 F=kq₁q₂/r² | K10: No class | L10: 4A.9 W=qV | M10: 4A.10 F=qE | N10: 4B.1 magnetic field model & 4B.2 B-field comparisons | O10: =SUM(P10:T10) -> 5 | P10: SACU3AOS1 Monday B Afternoon | Q10: 2 | R10: 1 | S10: 2 | T10: VCE Formal | U10: 4A.5 PE changes (qualitative) & 4A.6 static/changing, uniform/non | V10: 4A.7 E=kQ/r², E=V/d | W10: 4A.8 F=kq₁q₂/r² | X10: 4A.9 W=qV | Y10: 4A.10 F=qE | Z10: 1B [5.25p] Circular motion | AA10: 8 | AB10: 1B.5 Fnet=mg tan θ | AC10: 1B.5: Apply formula Fnet = mg tan θ for banked circular motion [1p]
A11: 44935 | B11: =B10+7 -> 46111 | C11: A | D11: =SUM(E11:I11) -> 5 | E11: 2 | F11: Aths | G11: 1 | H11: 2 | I11: Good Friday | J11: 4B.3 B-fields: magnets/wires/solenoids & 4B.4 field interactions | K11: 4B.5 F=nIlB | L11: 4B.6 DC motor operation & 4B.7 motor torque factors | M11: 4B.8 F=qvB, qvB=mv²/r | N11: 4B.9 accelerators & UCM | O11: =SUM(P11:T11) -> 2 | Q11: Aths | R11: 1 | S11: 1 | T11: Good Friday | U11: Aths | V11: Aths | W11: 4B.1 magnetic field model & 4B.2 B-field comparisons | X11: 4B.3 B-fields: magnets/wires/solenoids & 4B.4 field interactions | Y11: No class | Z11: 1B [5.25p] Circular motion | AA11: 9 | AB11: 1B.6 vertical circular FBDs | AC11: 1B.6: Draw free-body diagrams for vertical circular motion [0.5p]
D12: =SUM(E12:I12) -> 0 | O12: =SUM(P12:T12) -> 0 | Z12: 1B [5.25p] Circular motion | AA12: 10 | AB12: 1B.7 N/T & Fc equations (vertical) | AC12: 1B.7: Write equations relating normal/tension force to centripetal force in vertical circular motion [0.75p]
A13: 44958 | B13: =B11+21 -> 46132 | C13: B | D13: =SUM(E13:I13) -> 3 | E13: Secondary Assembly | G13: 1 | H13: 2 | J13: Secondary Assembly | K13: No class | L13: 5A.1 PV cell DC production & 5A.2 PV energy transforms | M13: 5A.3 inverter function & 5A.4 series/parallel PV panels | N13: 5B.1 induced emf situations & 5B.2 ΦB=B⊥A, Wb units | O13: =SUM(P13:T13) -> 5 | P13: Secondary Assembly | Q13: 2 | R13: 1 | S13: 2 | U13: 4B.5 F=nIlB | V13: 4B.6 DC motor operation & 4B.7 motor torque factors | W13: 4B.8 F=qvB, qvB=mv²/r | X13: 4B.9 accelerators & UCM | Y13: 5A.1 PV cell DC production & 5A.2 PV energy transforms | Z13: 1B [5.25p] Circular motion | AA13: 11 | AB13: 1B.8 v=2πr/T, T=1/f | AC13: 1B.8: Solve problems using v = 2πr/T and T = 1/f for vertical circular motion [0.5p]
A14: 44959 | B14: =B13+7 -> 46139 | C14: A | D14: =SUM(E14:I14) -> 5 | E14: 2 | G14: 1 | H14: 2 | J14: 5B.3 EM induction explanation | K14: 5B.4 ε=−NΔΦ/Δt | L14: 5B.5 Lenz's law | M14: 5B.6 induced I needs circuit & 5C.1 DC generator operation | N14: 5C.2 split ring commutator role & 5C.3 DC V-t graph shape | O14: =SUM(P14:T14) -> 4 | Q14: 2 | R14: 1 | S14: 1 | U14: 5A.3 inverter function & 5A.4 series/parallel PV panels | V14: 5B.1 induced emf situations & 5B.2 ΦB=B⊥A, Wb units | W14: 5B.3 EM induction explanation | X14: 5B.4 ε=−NΔΦ/Δt | Y14: No class | Z14: 1C [1p] Projectile motion | AA14: 12 | AB14: 1C.1 projectile path & air resistance | AC14: 1C.1: Describe projectile flight path and effects of air resistance [0.25p]
A15: 44960 | B15: =B14+7 -> 46146 | C15: B | D15: =SUM(E15:I15) -> 4 | E15: 1 | F15: SACU3AOS2 Monday B Afternoon | G15: 1 | H15: 2 | J15: 5C.4 V-t graphs vs coil number & 5D.1 AC generator operation | K15: No class | L15: 5D.2 slip rings role & 5D.3 sinusoidal V-t analysis | M15: 6A.1 Vrms=Vp/√2 | N15: 6A.2 Irms=Ip/√2 & 6A.3 P=VrmsIrms | O15: =SUM(P15:T15) -> 5 | P15: SACU3AOS2 Monday B Afternoon | Q15: 2 | R15: 1 | S15: 2 | U15: 5B.5 Lenz's law | V15: 5B.6 induced I needs circuit & 5C.1 DC generator operation | W15: 5C.2 split ring commutator role & 5C.3 DC V-t graph shape | X15: 5C.4 V-t graphs vs coil number & 5D.1 AC generator operation | Y15: 5D.2 slip rings role & 5D.3 sinusoidal V-t analysis | Z15: 1C [1p] Projectile motion | AA15: 13 | AB15: 1C.2 projectile component calcs | AC15: 1C.2: Solve projectile motion questions using vertical/horizontal components [0.75p]
A16: 44961 | B16: =B15+7 -> 46153 | C16: A | D16: =SUM(E16:I16) -> 5 | E16: 2 | G16: 1 | H16: 2 | J16: 6B.1 transformers & flux & 6B.2 step-up/step-down | K16: 6B.3 ideal vs real transformers & 6B.4 N₁/N₂=V₁/V₂=I₂/I₁ | L16: 6B.5 turns ratio calcs | M16: 6C.1 P=I²R, E=I²Rt | N16: 6C.2 transmission losses | O16: =SUM(P16:T16) -> 4 | Q16: 2 | R16: 1 | S16: 1 | U16: 6A.1 Vrms=Vp/√2 | V16: 6A.2 Irms=Ip/√2 & 6A.3 P=VrmsIrms | W16: 6B.1 transformers & flux & 6B.2 step-up/step-down | X16: 6B.3 ideal vs real transformers & 6B.4 N₁/N₂=V₁/V₂=I₂/I₁ | Y16: No class | Z16: 2A [4.25p] Work and energy | AA16: 14 | AB16: 2A.1 W=Fs cos θ | AC16: 2A.1: Apply formula W = Fs cos θ [0.5p]
A17: 44962 | B17: =B16+7 -> 46160 | C17: B | D17: =SUM(E17:I17) -> 4 | E17: 1 | G17: 1 | H17: 2 | J17: Catchup / Assessment | K17: No class | L17: Catchup / Assessment | N17: Catchup / Assessment | O17: =SUM(P17:T17) -> 5 | Q17: 2 | R17: 1 | S17: 2 | U17: 6B.5 turns ratio calcs | V17: 6C.1 P=I²R, E=I²Rt | W17: 6C.2 transmission losses | X17: Catchup / Assessment | Y17: Catchup / Assessment | Z17: 2A [4.25p] Work and energy | AA17: 15 | AB17: 2A.2 work needs parallel force | AC17: 2A.2: Understand work requires force parallel to motion [0.25p]
A18: 44963 | B18: =B17+7 -> 46167 | C18: A | D18: =SUM(E18:I18) -> 5 | E18: 2 | G18: 1 | H18: 2 | I18: Student free day | J18: 7A.1 accel charges → EM waves & 7A.2 EM waves: E⊥B at c | K18: 7A.3 superposition → standing waves | L18: 7A.4 standing wave analysis | M18: 7A.5 diffraction & gap width & 7A.6 λ/w ratio & imaging | N18: 7A.7 Young's double slit | O18: =SUM(P18:T18) -> 4 | Q18: 2 | R18: 1 | S18: 1 | T18: Student free day | U18: 7A.1 accel charges → EM waves & 7A.2 EM waves: E⊥B at c | V18: 7A.3 superposition → standing waves | W18: 7A.4 standing wave analysis | X18: 7A.5 diffraction & gap width & 7A.6 λ/w ratio & imaging | Y18: No class | Z18: 2A [4.25p] Work and energy | AA18: 16 | AB18: 2A.3 work from F-s graph | AC18: 2A.3: Calculate work as area under force–displacement graph [0.5p]
A19: 44964 | B19: =B18+7 -> 46174 | C19: B | D19: =SUM(E19:I19) -> 4 | E19: 1 | F19: SACU3AOS3 Monday B Afternoon | G19: 1 | H19: 2 | J19: 7A.8 path diff: nλ, (n+½)λ | K19: No class | L19: 7A.9 Δx=λL/d | M19: 7B.1 E=hf=hc/λ | N19: 7B.2 photoelectric evidence | O19: =SUM(P19:T19) -> 5 | P19: SACU3AOS3 Monday B Afternoon | Q19: 2 | R19: 1 | S19: 2 | U19: 7A.7 Young's double slit | V19: 7A.8 path diff: nλ, (n+½)λ | W19: 7A.9 Δx=λL/d | X19: 7B.1 E=hf=hc/λ | Y19: 7B.2 photoelectric evidence | Z19: 2A [4.25p] Work and energy | AA19: 17 | AB19: 2A.4 energy conservation | AC19: 2A.4: Understand energy is conserved [0.5p]
A20: 44965 | B20: =B19+7 -> 46181 | C20: A | D20: =SUM(E20:I20) -> 3 | E20: King's Birthday | G20: 1 | H20: 2 | J20: King's Birthday | K20: King's Birthday | L20: 7B.3 photoelectric graphs | M20: 8A.1 electron diffraction patterns | N20: 8A.2 diffraction → wave nature | O20: =SUM(P20:T20) -> 4 | P20: King's Birthday | Q20: 2 | R20: 1 | S20: 1 | U20: King's Birthday | V20: King's Birthday | W20: 7B.3 photoelectric graphs | X20: 8A.1 electron diffraction patterns | Y20: No class | Z20: 2A [4.25p] Work and energy | AA20: 18 | AB20: 2A.5 Ek=½mv², Eg=mgΔh | AC20: 2A.5: Apply formulas for kinetic and gravitational potential energy (Ek = ½mv², Eg = mgΔh) [1p]
A21: 44966 | B21: =B20+7 -> 46188 | C21: B | D21: =SUM(E21:I21) -> 5 | E21: 2 | F21: GAT | G21: 1 | H21: 2 | I21: 10 11 | J21: 8A.3 photon vs electron patterns | K21: No class | L21: 8A.4 λ=h/p | M21: 8B.1 quantisation concepts & 8B.2 p=h/λ | N21: 8B.3 photon vs matter momentum & 8B.4 emission spectra | O21: =SUM(P21:T21) -> 3 | Q21: GAT | R21: 1 | S21: 2 | T21: 10 11 | U21: 8A.2 diffraction → wave nature | V21: 8A.3 photon vs electron patterns | W21: GAT | X21: 8A.4 λ=h/p | Y21: 8B.1 quantisation concepts & 8B.2 p=h/λ | Z21: 2A [4.25p] Work and energy | AA21: 19 | AB21: 2A.6 Ek↔Eg transformations | AC21: 2A.6: Analyse energy transformations between Ek and Eg [1.5p]
A22: 44967 | B22: =B21+7 -> 46195 | C22: A | D22: =SUM(E22:I22) -> 1 | E22: 1 | F22: HPA | G22: HPA | H22: HPA | I22: HPA | J22: 8B.5 absorption spectra & 8B.6 ΔE=hc/λ from spectra | K22: HPA | L22: HPA | M22: HPA | N22: HPA | O22: =SUM(P22:T22) -> 0 | Q22: HPA | R22: HPA | S22: HPA | T22: HPA | U22: 8B.3 photon vs matter momentum & 8B.4 emission spectra | V22: HPA | W22: HPA | X22: HPA | Y22: HPA | Z22: 2B [3.75p] Momentum and impulse | AA22: 20 | AB22: 2B.1 p=mv | AC22: 2B.1: Apply formula p = mv for momentum [0.5p]
O23: =SUM(P23:T23) -> 0 | Z23: 2B [3.75p] Momentum and impulse | AA23: 21 | AB23: 2B.2 momentum conservation | AC23: 2B.2: Apply conservation of momentum to collisions [1p]
A24: 44986 | B24: =B22+28 -> 46223 | C24: B | D24: =SUM(E24:I24) -> 3 | E24: Secondary Assembly | G24: 1 | H24: 2 | J24: Secondary Assembly | K24: No class | L24: 8B.7 ΔE=hf transitions | M24: 8B.8 single particle duality | N24: 9A.1 inertial frames & 9A.2 inertial vs non-inertial | O24: =SUM(P24:T24) -> 5 | P24: Secondary Assembly | Q24: 2 | R24: 1 | S24: 2 | U24: 8B.5 absorption spectra | V24: 8B.6 ΔE=hc/λ from spectra | W24: 8B.7 ΔE=hf transitions | X24: 8B.8 single particle duality | Y24: 9A.1 inertial frames & 9A.2 inertial vs non-inertial | Z24: 2B [3.75p] Momentum and impulse | AA24: 22 | AB24: 2B.3 elastic vs inelastic | AC24: 2B.3: Determine if collisions are elastic or inelastic [0.75p]
A25: 44987 | B25: =B24+7 -> 46230 | C25: A | D25: =SUM(E25:I25) -> 5 | E25: 2 | G25: 1 | H25: 2 | J25: 9A.3 relativity concept | K25: 9A.4 SR postulates | L25: 9A.5 Michelson-Morley & aether & 9A.6 SR vs classical | M25: 9B.1 proper time t₀ & 9B.2 dilated time t | N25: 9B.3 proper length L₀ & 9B.4 identify proper length | O25: =SUM(P25:T25) -> 4 | Q25: 2 | R25: 1 | S25: 1 | U25: 9A.3 relativity concept | V25: 9A.4 SR postulates | W25: 9A.5 Michelson-Morley & aether & 9A.6 SR vs classical | X25: 9B.1 proper time t₀ & 9B.2 dilated time t | Y25: No class | Z25: 2B [3.75p] Momentum and impulse | AA25: 23 | AB25: 2B.4 I=Δp=mΔv=FΔt | AC25: 2B.4: Apply impulse formula I = Δp = mΔv = FavΔt [0.75p]
A26: 44988 | B26: =B25+7 -> 46237 | C26: B | D26: =SUM(E26:I26) -> 4 | E26: 1 | G26: 1 | H26: 2 | J26: 9B.5 contraction direction | K26: No class | L26: 9B.6 L=L₀/γ, t=t₀γ | M26: 9B.7 accelerators & l.c. & 9B.8 GPS & time dilation | N26: 9B.9 speed effects on t,L & 9C.1 muon t dilation (Earth) | O26: =SUM(P26:T26) -> 5 | Q26: 2 | R26: 1 | S26: 2 | U26: 9B.3 proper length L₀ & 9B.4 identify proper length | V26: 9B.5 contraction direction | W26: 9B.6 L=L₀/γ, t=t₀γ | X26: 9B.7 accelerators & l.c. & 9B.8 GPS & time dilation | Y26: 9B.9 speed effects on t,L & 9C.1 muon t dilation (Earth) | Z26: 2B [3.75p] Momentum and impulse | AA26: 24 | AB26: 2B.5 impulse from F-t graph | AC26: 2B.5: Calculate impulse as area under force–time graph [0.75p]
A27: 44989 | B27: =B26+7 -> 46244 | C27: A | D27: =SUM(E27:I27) -> 5 | E27: 2 | F27: X Country | G27: 1 | H27: 2 | J27: 9C.2 muon l.c. (muon frame) & 9D.1 E=mc² | K27: 9D.2 Etot=γmc², Ek=(γ–1)mc² | L27: 9D.3 ΔE=Δmc² & 9D.4 accelerators → new elements & 9D.5 γ vs v graph | M27: Catchup / Assessment | N27: Catchup / Assessment | O27: =SUM(P27:T27) -> 2 | Q27: X Country | R27: 1 | S27: 1 | U27: 9C.2 muon l.c. (muon frame) & 9D.1 E=mc² | V27: 9D.2 Etot=γmc², Ek=(γ–1)mc² | W27: 9D.3 ΔE=Δmc² & 9D.4 accelerators → new elements & 9D.5 γ vs v graph | X27: Catchup / Assessment | Y27: No class | Z27: 2C [2.25p] Springs | AA27: 25 | AB27: 2C.1 k & Es from F-x graphs | AC27: 2C.1: Understand spring constant and elastic potential energy from force–extension graphs [0.5p] | AD27: e
A28: 44990 | B28: =B27+7 -> 46251 | C28: B | D28: =SUM(E28:I28) -> 4 | E28: 1 | F28: SACU4AOS1 Monday B Afternoon | G28: 1 | H28: 2 | J28: Catchup / Assessment | K28: No class | L28: Investigation planning | M28: Investigation planning | N28: Investigation planning | O28: =SUM(P28:T28) -> 5 | P28: SACU4AOS1 Monday B Afternoon | Q28: 2 | R28: 1 | S28: 2 | U28: Catchup / Assessment | V28: Catchup / Assessment | W28: Investigation planning | X28: Investigation planning | Y28: Investigation planning | Z28: 2C [2.25p] Springs | AA28: 26 | AB28: 2C.2 F=–kx, Es=½kx² | AC28: 2C.2: Apply Hooke's law (F = –kx) and elastic PE formula (Es = ½kx²) [0.5p]
A29: 44991 | B29: =B28+7 -> 46258 | C29: A | D29: =SUM(E29:I29) -> 5 | E29: 2 | G29: 1 | H29: 2 | J29: 9 Periods SAC Investigation SACU4AOS2 | K29: Investigation | L29: Investigation | M29: Investigation | N29: Investigation | O29: =SUM(P29:T29) -> 4 | Q29: 2 | R29: 1 | S29: 1 | U29: 9 Periods SAC Investigation SACU4AOS2 | V29: Investigation | W29: Investigation | X29: Investigation | Y29: No class | Z29: 2C [2.25p] Springs | AA29: 27 | AB29: 2C.3 spring energy transforms | AC29: 2C.3: Analyse energy transformations in spring systems [0.5p]
A30: 44992 | B30: =B29+7 -> 46265 | C30: B | D30: =SUM(E30:I30) -> 4 | E30: 1 | G30: 1 | H30: 2 | J30: Investigation | K30: No class | L30: Investigation | M30: Investigation | N30: Investigation | O30: =SUM(P30:T30) -> 5 | Q30: 2 | R30: 1 | S30: 2 | U30: Investigation | V30: Investigation | W30: Investigation | X30: Investigation | Y30: Investigation | Z30: 2C [2.25p] Springs | AA30: 28 | AB30: 2C.4 oscillating spring energy | AC30: 2C.4: Describe energy transformations in oscillating springs [0.25p]
A31: 44993 | B31: =B30+7 -> 46272 | C31: A | E31: 2 | G31: 1 | H31: 2 | J31: Practice Exams | K31: Practice Exams | L31: Practice Exams | M31: Practice Exams | N31: Practice Exams | Q31: 2 | R31: 1 | S31: 1 | U31: Practice Exams | V31: Practice Exams | W31: Practice Exams | X31: Practice Exams | Y31: No class | Z31: 2C [2.25p] Springs | AA31: 29 | AB31: 2C.5 mg=kx equilibrium | AC31: 2C.5: Apply mg = kx for vertical spring equilibrium [0.5p]
A32: 44994 | B32: =B31+7 -> 46279 | C32: B | E32: 1 | G32: 1 | H32: 2 | J32: Practice Exams | K32: No class | L32: Practice Exams | M32: Practice Exams | N32: Practice Exams | Q32: 2 | R32: 1 | S32: 2 | U32: Practice Exams | V32: Practice Exams | W32: Practice Exams | X32: Practice Exams | Y32: Practice Exams | Z32: 3A [2p] Gravity and gravitational fields | AA32: 30 | AB32: 3A.1 g-field shape & monopole | AC32: 3A.1: Understand gravitational field direction, shape, and monopole nature [0.5p]
D33: =SUM(E33:I33) -> 0 | O33: =SUM(P33:T33) -> 0 | Z33: 3A [2p] Gravity and gravitational fields | AA33: 31 | AB33: 3A.2 inverse square (gravity) | AC33: 3A.2: Understand inverse square law for gravitational fields about point masses [0.5p]
A34: 45017 | B34: =B32+21 -> 46300 | C34: A | E34: 2 | G34: 1 | H34: 2 | J34: Practice Exams | K34: Practice Exams | L34: Practice Exams | M34: Practice Exams | N34: Practice Exams | Q34: 2 | R34: 1 | S34: 1 | U34: Practice Exams | V34: Practice Exams | W34: Practice Exams | X34: Practice Exams | Y34: No class | Z34: 3A [2p] Gravity and gravitational fields | AA34: 32 | AB34: 3A.3 g=GM/r², Fg=Gm₁m₂/r² | AC34: 3A.3: Apply g = GM/r² and Fg = Gm₁m₂/r² [1p]
A35: 45018 | B35: =B34+7 -> 46307 | C35: B | E35: 1 | G35: 1 | H35: 2 | J35: Practice Exams | K35: No class | L35: Practice Exams | M35: Practice Exams | N35: Practice Exams | Q35: 2 | R35: 1 | S35: 2 | U35: Practice Exams | V35: Practice Exams | W35: Practice Exams | X35: Practice Exams | Y35: Practice Exams | Z35: 3B [1p] Gravitational potential energy | AA35: 33 | AB35: 3B.1 Eg=mgΔh | AC35: 3B.1: Determine GPE changes using Eg = mgΔh [0.5p]
A36: 45019 | B36: =B35+7 -> 46314 | C36: A | D36: =SUM(E36:I36) -> 0 | E36: 12 Val | J36: 12 Val | O36: =SUM(P36:T36) -> 0 | P36: 12 Val | U36: 12 Val | Y36: No class | Z36: 3B [1p] Gravitational potential energy | AA36: 34 | AB36: 3B.2 GPE from graphs | AC36: 3B.2: Calculate GPE from area under force–distance and field–distance graphs [0.5p]
A37: 45020 | B37: =B36+7 -> 46321 | C37: B | D37: =SUM(E37:I37) -> 0 | K37: No class | O37: =SUM(P37:T37) -> 0 | Z37: 3C [1p] Orbiting satellites | AA37: 35 | AB37: 3C.1 Fg & FN for satellites | AC37: 3C.1: Apply concepts of Fg and FN for satellites in orbit [0.5p]
A38: 45021 | B38: =B37+7 -> 46328 | C38: A | D38: =SUM(E38:I38) -> 0 | E38: Cup Weekend | F38: Cup Weekend | J38: Cup Weekend | K38: Cup Weekend | O38: =SUM(P38:T38) -> 0 | P38: Cup Weekend | Q38: Cup Weekend | U38: Cup Weekend | V38: Cup Weekend | W38: Cup Weekend | Z38: 3C [1p] Orbiting satellites | AA38: 36 | AB38: 3C.2 a=v²/r=4π²r/T² | AC38: 3C.2: Model satellite motion using a = v²/r = 4π²r/T² [0.5p]
A39: 45022 | B39: =B38+7 -> 46335 | C39: B | D39: =SUM(E39:I39) -> 0 | I39: 10 11 Exams | O39: =SUM(P39:T39) -> 0 | T39: 10 11 Exams | Z39: 4A [7p] Electric fields and forces | AA39: 37 | AB39: 4A.1 electric field model | AC39: 4A.1: Describe electricity using field model [0.5p]
A40: 45023 | B40: =B39+7 -> 46342 | C40: B | D40: =SUM(E40:I40) -> 0 | E40: 10 11 Exams | F40: 10 11 Exams | G40: 10 11 Exams | H40: 10 11 Exams | I40: Student free day | O40: =SUM(P40:T40) -> 0 | P40: 10 11 Exams | Q40: 10 11 Exams | R40: 10 11 Exams | S40: 10 11 Exams | T40: Student free day | Z40: 4A [7p] Electric fields and forces | AA40: 38 | AB40: 4A.2 E-field comparisons | AC40: 4A.2: Compare electric fields (direction, shapes, dipoles/monopoles) [0.5p]
...

Sheet Physics 12 2026
A1: When | B1: Week of | D1: Periods | E1: M | F1: T | G1: W | H1: T | I1: F | K1: Monday | L1: Monday | M1: Thursday | N1: Thursday | O1: Friday | P1: Monday | Q1: Monday | R1: Wednesday | S1: Friday | T1: Friday
A2: 44927 | B2: 46055 | C2: A | D2: =SUM(E2:I2) -> 3 | E2: No classes | F2: Founders Day Assembly | G2: 2 | I2: 1 | K2: No classes | L2: No classes | M2: 1A.1 wave motion examples; 1A.2 energy transfer no matter | N2: 1A.3 transverse vs longitudinal | O2: 1A.4 A, v, f, T, λ wave terms; 1A.5 λ from v (medium) & f (source) | S2: 1A Kinematics recap | T2: 1B Forces recap | U2: 1 | V2: 1A.1 wave motion examples | W2: 1A.1 Recognise wave motion and give examples
A3: 44928 | B3: =B2+7 -> 46062 | C3: B | D3: =SUM(E3:I3) -> 4 | E3: 2 | G3: 1 | I3: 1 | K3: 1A.6 λ = v/f = vT calculations | L3: 1B.1 EM waves transverse E&M fields; 1B.2 Sun emits UV, visible, IR | M3: 1B.3 EM spectrum λ & f ranges; 1B.4 EM spectrum societal uses | N3: No class | O3: 1C.1 ray model reflection/refraction; 1C.2 refractive index definition | P3: 1C Inclined planes | Q3: 1D Connected bodies | R3: 1E Basic circular motion | S3: 1E Basic circular motion | T3: 1F Banked circular motion | U3: 2 | V3: 1A.2 energy transfer no matter | W3: 1A.2 Understand that wave motion transfers energy without transferring matter
A4: 44929 | B4: =B3+7 -> 46069 | C4: A | D4: =SUM(E4:I4) -> 5 | E4: 2 | G4: 2 | I4: 1 | K4: 1C.3 n₁v₁ = n₂v₂ equation | L4: 1C.4 Snell's law practicals; 1C.5 Snell's law refraction calcs | M4: 1C.6 ray model image formation | N4: 1C.7 total internal reflection pracs; 1C.8 critical angle prediction | O4: 1C.9 dispersion practicals | P4: 1F Banked circular motion | Q4: 1G Vertical circular motion | S4: 1G Vertical circular motion | T4: 1H Projectile motion | U4: 3 | V4: 1A.3 transverse vs longitudinal | W4: 1A.3 Distinguish between transverse and longitudinal waves
A5: 44930 | B5: =B4+7 -> 46076 | C5: B | D5: =SUM(E5:I5) -> 4 | E5: 2 | F5: Swim | G5: 1 | I5: 1 | K5: 1C.10 dispersion in prisms/lenses; 1C.11 rainbows & mirages formation | L5: 1C.12 Snell's law optical fibres | M5: 2A.1 thermal energy = Ek + Ep; 2A.2 temp ↔ thermal energy | N5: No class | O5: 2A.3 Celsius ↔ kelvin conversion; 2A.4 conduction/convection/radiation | P5: 1H Projectile motion | Q5: 1I Momentum and impulse | R5: 2A Kinetic energy, work and power | S5: 2B Elastic and inelastic collisions | T5: 2C Gravitational potential energy | U5: 4 | V5: 1A.4 A, v, f, T, λ wave terms | W5: 1A.4 Use amplitude (A), speed (v), frequency (f), period (T) and wavelength (λ) to describe the motion of waves
A6: 44931 | B6: =B5+7 -> 46083 | C6: A | D6: =SUM(E6:I6) -> 5 | E6: 2 | G6: 2 | I6: 1 | K6: 2A.5 specific heat capacity c | L6: 2A.6 latent heat L definition; 2A.7 temp/state change practicals | M6: 2A.8 thermal energy change analysis; 2A.9 Q = mcΔT calculations | N6: 2A.10 Q = mL calculations | O6: 2B.1 blackbody features | P6: Chapter 1 review | Q6: Chapter 1 review | S6: Questions from Chapter 2A B C | U6: 5 | V6: 1A.5 λ from v (medium) & f (source) | W6: 1A.5 Explain the wavelength of a wave as a result of the velocity (determined by the medium through which it travels) and the frequency (determined by the source)
A7: 44932 | B7: =B6+7 -> 46090 | C7: B | D7: =SUM(E7:I7) -> 2 | E7: Labour Day | G7: 1 | I7: 1 | K7: Labour Day | L7: Labour Day | M7: 2B.2 Wien's law λₘₐₓT = 2.90×10⁻³; 2B.3 blackbody total energy graphs | N7: No class | O7: 2B.4 thermal/EM radiation concepts | P7: 2C Gravitational potential energy | Q7: 2D Strain potential energy | R7: 2D Strain potential energy | S7: 2E Vertical spring-mass systems | T7: 2E Vertical spring-mass systems | U7: 6 | V7: 1A.6 λ = v/f = vT calculations | W7: 1A.6 Solve numerical problems using: λ = v/f = vT
A8: 44933 | B8: =B7+7 -> 46097 | C8: A | D8: =SUM(E8:I8) -> 5 | E8: 2 | G8: 2 | I8: 1 | K8: 3A.1 proton:neutron ratio stability; 3A.2 electrostatic/strong/weak forces | L8: 3A.3 electrostatic repulsion in nucleus | M8: 3A.4 strong nuclear force overcomes; 3A.5 weak force p↔n transformation | N8: 3A.6 binding energy curve | O8: AT U1AOS1 | P8: Chapter 2 review | Q8: U3 AOS1 review | S8: 3A Gravitational fields and forces | T8: 3A Gravitational fields and forces | U8: 7 | V8: 1B.1 EM waves transverse E&M fields | W8: 1B.1 Describe all electromagnetic waves as transverse vibrations of electric and magnetic fields that travel at speed, c, in a vacuum
A9: 44934 | B9: =B8+7 -> 46104 | C9: B | D9: =SUM(E9:I9) -> 3 | E9: 2 | G9: 1 | I9: VCE Formal | K9: 3B.1 α, β⁻, β⁺, γ properties; 3B.2 decay equations α, β⁻, β⁺, γ | L9: 3C.1 half-life concept; 3C.2 activity after n half-lives | M9: 3D.1 decay chains (e.g. U-238) | N9: No class | O9: VCE Formal | P9: 3B Gravitational potential energy in uniform and non-uniform fields | Q9: 3B Gravitational potential energy in uniform and non-uniform fields | R9: 3C Orbital Motion | S9: 3C Orbital Motion | T9: SAC Practice Task | U9: 8 | V9: 1B.2 Sun emits UV, visible, IR | W9: 1B.2 Describe electromagnetic radiation emitted from the Sun as mainly UV, visible and IR
A10: 44935 | B10: =B9+7 -> 46111 | C10: A | D10: =SUM(E10:I10) -> 4 | E10: 2 | F10: Aths | G10: 2 | I10: Good Friday | K10: 3E.1 radiation effects on humans; 3E.2 α, β, γ cell damage capacity | L10: 3E.3 low/high dose short/long term | M10: 3E.4 external vs internal sources; 3E.5 gray, sievert dose calcs | N10: 3E.6 medical radioisotopes therapy | O10: Good Friday | P10: Athletics | Q10: U3 AOS1 SAC TEST | S10: Chapter 3 review | T10: Chapter 3 review | U10: 9 | V10: 1B.3 EM spectrum λ & f ranges | W10: 1B.3 Recall approximate wavelength and frequency ranges of the radio, microwave, infrared, visible, ultraviolet, X-ray and gamma ray regions
D11: =SUM(E11:I11) -> 0 | U11: 10 | V11: 1B.4 EM spectrum societal uses | W11: 1B.4 Give examples of the different societal uses of regions of the electromagnetic spectrum from radio through to gamma rays
A12: 44958 | B12: =B10+21 -> 46132 | C12: B | D12: =SUM(E12:I12) -> 2 | E12: Secondary Assembly | G12: 1 | I12: 1 | K12: 4A.1 E = mc² nuclear energy; 4A.2 fission chain reactions | L12: 4A.3 mass/shape criticality; 4A.4 neutron absorbers & moderators | M12: 4B.1 fusion vs fission comparison; 4B.2 binding energy curve fusion/fission | N12: No class | O12: 4C.1 nuclear viability Australia; 4C.2 nuclear pros/cons Australia | P12: 4A Electric fields | Q12: 4A Electric fields | R12: 4B Magnetic fields | S12: 4B Magnetic fields | T12: 4C Magnetic forces on charged particles | U12: 11 | V12: 1C.1 ray model reflection/refraction | W12: 1C.1 Use a ray model with wave crests to describe reflection and refraction of light
A13: 44959 | B13: =B12+7 -> 46139 | C13: A | D13: =SUM(E13:I13) -> 5 | E13: 2 | G13: 2 | I13: 1 | K13: 5A.1 metal = sea of electrons; 5A.2 current = drift velocity e⁻ | L13: 5A.3 charge/current analogies | M13: 5A.4 circuit symbols & diagrams; 5A.5 ammeter measures current | N13: 5A.6 I = Q/t calculations | O13: AT U1AOS2 | P13: 4C Magnetic forces on charged particles | Q13: 4D DC motors | R13: ANZAX | S13: Chapter 4 review | T13: U3 AOS2 review | U13: 12 | V13: 1C.10 dispersion in prisms/lenses | W13: 1C.10 Qualitatively analyse situations involving dispersion of visible light in prisms and lenses
A14: 44960 | B14: =B13+7 -> 46146 | C14: B | D14: =SUM(E14:I14) -> 4 | E14: 2 | G14: 1 | I14: 1 | K14: 5B.1 charge separation = V = energy; 5B.2 V = E/Q and E = VIt | L14: 5B.3 voltage/current analogies; 5B.4 voltmeter measures V | M14: 5B.5 ammeter series, voltmeter parallel | N14: No class | O14: 5C.1 I-V for ohmic resistance; 5C.2 R = V/I Ohm's law | P14: Chapter 4 review | Q14: 4D DC motors | R14: MOTOR DISASSEMBLY | U14: 13 | V14: 1C.11 rainbows & mirages formation | W14: 1C.11 Qualitatively explain the formation of rainbows and mirages using a ray model of light
A15: 44961 | B15: =B14+7 -> 46153 | C15: A | D15: =SUM(E15:I15) -> 5 | E15: 2 | G15: 2 | I15: 1 | J15: Production week | K15: 5C.3 current continuous in series | L15: 5C.4 V drops across each R; 5C.5 R_total = R₁ + R₂ + ... series | M15: 5C.6 voltage divider Vout calcs | N15: 5D.1 parallel = junctions, paths; 5D.2 current splits at junctions | O15: 5D.3 same V across parallel branches; 5D.4 1/R = 1/R₁ + 1/R₂ parallel | Q15: U3 AOS2 SAC Data Analysis | S15: 5A EMF and Faraday’s law | T15: 5B Direction of induced current and Lenz’s law 274 | U15: 14 | V15: 1C.12 Snell's law optical fibres | W15: 1C.12 Apply Snell's law to analyse qualitatively and quantitatively the operation of optical fibres for communication
A16: 44962 | B16: =B15+7 -> 46160 | C16: B | D16: =SUM(E16:I16) -> 4 | E16: 2 | G16: 1 | I16: 1 | K16: 5D.5 I-V graphs equivalent R | L16: 5E.1 P = E/t power formula; 5E.2 P = VI, P = I²R, P = V²/R | M16: 5E.3 power in series vs parallel; 5E.4 series vs parallel advantages | N16: No class | O16: 6A.1 diode I-V characteristic; 6A.2 LED I-V characteristic | P16: 6A Electricity recap | Q16: 6B Transformers and comparing AC and DC power | S16: 6B Transformers and comparing AC and DC power | T16: 6C Transmission of power | U16: 15 | V16: 1C.2 refractive index definition | W16: 1C.2 Define refractive index of transparent substances
A17: 44963 | B17: =B16+7 -> 46167 | C17: A | D17: =SUM(E17:I17) -> 4 | E17: 2 | G17: 2 | I17: Student free day | K17: 6A.3 variable resistor/potentiometer; 6A.4 LDR resistance vs light | L17: 6A.5 thermistor resistance vs temp | M17: 6A.6 voltage divider with components; 6A.7 LDR/thermistor divider circuits | N17: 6A.8 variable component circuits | O17: Student free day | U17: 16 | V17: 1C.3 n₁v₁ = n₂v₂ equation | W17: 1C.3 Use the equation: n₁v₁ = n₂v₂
A18: 44964 | B18: =B17+7 -> 46174 | C18: B | D18: =SUM(E18:I18) -> 4 | E18: 2 | G18: 1 | I18: 1 | K18: 6B.1 redraw circuits as diagrams; 6B.2 household parallel AC 230V; 6B.3 series vs parallel justification | L18: 6B.4 household power/energy calcs; 6B.5 kilowatt-hour (kWh) energy | M18: 6C.1 electric shock causes/effects; 6C.2 danger current thresholds; 6C.3 230V 50Hz safety devices | N18: No class | O18: 6C.4 3-pin plug active/neutral/earth; 6C.5 earth = low R path to 0V; 6C.6 fuse/circuit breaker/RCD | P18: 6C Transmission of power | Q18: Chapter 6 review | R18: Chapter 6 review | S18: AOS3 review | T18: AOS3 review | U18: 17 | V18: 1C.4 Snell's law practicals | W18: 1C.4 Carry out practical investigations involving Snell's law
A19: 44965 | B19: =B18+7 -> 46181 | C19: A | D19: =SUM(E19:I19) -> 3 | E19: King's Birthday | G19: 2 | I19: 1 | K19: King's Birthday | L19: King's Birthday | M19: AT U1AOS3 | N19: Practice Exam | O19: Practice Exam | P19: U3 AOS3 SAC Structured questions | Q19: 7A Waves recap | S19: 7B Wave interference and path difference | T19: 7C Standing waves | U19: 18 | V19: 1C.5 Snell's law refraction calcs | W19: 1C.5 Apply Snell's law to analyse qualitative and quantitative refraction situations of visible light
A20: 44966 | B20: =B19+7 -> 46188 | C20: B | D20: =SUM(E20:I20) -> 2 | E20: 2 | F20: GAT | G20: 10-11 exams | H20: 10-11 exams | I20: 10-11 exams | K20: 10-11 exams | L20: 10-11 exams | M20: 10-11 exams | N20: 10-11 exams | O20: 10-11 exams | U20: 19 | V20: 1C.6 ray model image formation | W20: 1C.6 Qualitatively, using a ray model, explain the formation of images
A21: 44967 | B21: =B20+7 -> 46195 | C21: A | D21: =SUM(E21:I21) -> 0 | E21: 10-11 exams | F21: HPA | G21: HPA | H21: HPA | I21: HPA | K21: 10-11 exams | L21: HPA | M21: HPA | N21: HPA | O21: HPA | P21: 7C Standing waves | Q21: 7D Diffraction | S21: Chapter 7 review | U21: 20 | V21: 1C.7 total internal reflection pracs | W21: 1C.7 Carry out practical investigations involving total and partial internal reflection
P22: who | Q22: knows | R22: what | S22: happened | T22: here | U22: 21 | V22: 1C.8 critical angle prediction | W22: 1C.8 Apply Snell's law to predict the critical angle at media interfaces
A23: 44986 | B23: =B21+28 -> 46223 | C23: B | D23: =SUM(E23:I23) -> 2 | E23: Secondary Assembly | G23: 1 | I23: 1 | K23: 7A.1 vector vs scalar definition; 7A.2 common vectors & scalars | L23: 7A.3 straight-line vector addition | M23: 7A.4 vector components | N23: No class | O23: 7A.5 find unknown vector | U23: 22 | V23: 1C.9 dispersion practicals | W23: 1C.9 Carry out practical investigations involving dispersion of visible light
A24: 44987 | B24: =B23+7 -> 46230 | C24: A | D24: =SUM(E24:I24) -> 5 | E24: 2 | G24: 2 | I24: 1 | K24: 7B.1 interpret s-t graph; 7B.2 gradient s-t = velocity | L24: 7B.3 interpret v-t graph | M24: 7B.4 gradient v-t = acceleration; 7B.5 area under v-t = displacement | N24: 7B.6 interpret a-t graph | O24: 7B.7 area under a-t = Δv | P24: 5B Direction of induced current and Lenz’s law 274 | R24: 5C Alternators and DC generators | S24: 5D Photovoltaic cells | T24: Chapter 5 review | U24: 23 | V24: 2A.1 thermal energy = Ek + Ep | W24: 2A.1 Describe thermal energy as the sum of the random kinetic energy and potential energy of the atoms and molecules of an object or system
A25: 44988 | B25: =B24+7 -> 46237 | C25: B | D25: =SUM(E25:I25) -> 4 | E25: 2 | G25: 1 | I25: 1 | K25: 7C.1 SUVAT equations | L25: 8A.1 p = mv momentum; 8A.2 momentum conservation | M25: 8A.3 collision momentum problems | N25: No class | O25: Ch7 Test | U25: 24 | V25: 2A.10 Q = mL calculations | W25: 2A.10 Use the equation Q = mL to calculate the energy needed to change the state of a substance
A26: 44989 | B26: =B25+7 -> 46244 | C26: A | D26: =SUM(E26:I26) -> 5 | E26: 2 | F26: X Country | G26: 2 | I26: 1 | K26: 8A.4 elastic vs inelastic maths | L26: 8A.5 I = Δp = mΔv = FΔt impulse | M26: 8A.6 area under F-t = impulse | N26: 8B.1 Newton's three laws; 8B.2 add forces → net force | O26: 8B.3 Fnet = ma calculations | P26: 8B Young’s double slit experiment | Q26: 8A Electromagnetic waves | S26: 9A Experimental design of the photoelectric effect | T26: 9B Changing intensity in the photoelectric effect | U26: 25 | V26: 2A.2 temp ↔ thermal energy | W26: 2A.2 Understand that increases and decreases of temperature are related to increases and decreases of thermal energy in a system
A27: 44990 | B27: =B26+7 -> 46251 | C27: B | D27: =SUM(E27:I27) -> 4 | E27: 2 | G27: 1 | I27: 1 | J27: Science Week | K27: 8B.4 normal force concept; 8B.5 Newton's laws applications | L27: 8B.6 force naming convention | M27: 8B.7 mass vs weight (Fg) | N27: No class | O27: 8B.8 Fg at centre of mass | P27: 9C Changing frequency in the photoelectric effect | Q27: 9D What the photoelectric effect means | R27: 9A Experimental design of the photoelectric effect | S27: 10A Comparing light and matter | T27: 10B Absorption and emission spectra | U27: 26 | V27: 2A.3 Celsius ↔ kelvin conversion | W27: 2A.3 Convert temperatures between Celsius and kelvin
A28: 44991 | B28: =B27+7 -> 46258 | C28: A | D28: =SUM(E28:I28) -> 5 | E28: 2 | G28: 2 | I28: 1 | K28: 8B.9 motion & vehicle safety | L28: 8C.1 τ = r⊥F torque; 8C.2 rotational equilibrium Στ = 0 | M28: 8C.3 translational equilibrium ΣF = 0 | N28: 9A.1 work needs parallel force; 9A.2 W = Fs cos θ | O28: Ch8 Test | Q28: 11A Special relativity concepts | S28: 11A Special relativity concepts | T28: 11B Length contraction and time dilation | U28: 27 | V28: 2A.4 conduction/convection/radiation | W28: 2A.4 Analyse qualitatively thermal energy transfers in terms of conduction, convection, radiation and evaporation using a particle model
A29: 44992 | B29: =B28+7 -> 46265 | C29: B | D29: =SUM(E29:I29) -> 4 | E29: 2 | G29: 1 | I29: 1 | K29: 9A.3 area under F-s = work | L29: 9B.1 Eg = mgΔh; 9B.2 Ek = ½mv² | M29: 9B.3 Ek ∝ v² | N29: No class | O29: 9B.4 ΔEk = ½mv² − ½mu²; 9B.5 closed system energy conserved | P29: 11B Length contraction and time dilation | Q29: 11B Length contraction and time dilation | R29: 11B Length contraction and time dilation | S29: 11C Relativity examples | T29: 11D Mass-energy | U29: 28 | V29: 2A.5 specific heat capacity c | W29: 2A.5 Define specific heat capacity, c
